<?xml version="1.0" ?>
<robot xmlns:xacro="http://www.ros.org/wiki/xacro" name="dd_robot">
  <!-- Properties -->
  <xacro:property name="wheel_radius" value="0.0762"/>
  <xacro:property name="wheel_width" value="0.04318"/>
  <xacro:property name="base_length" value="0.6096"/>
  <xacro:property name="base_width" value="0.4191"/>
  <xacro:property name="base_height" value="0.15"/>
  <xacro:property name="wheel_separation" value="0.48"/>
  <xacro:property name="wheel_diameter" value="0.1524"/>

  <!-- Base Link -->
  <link name="base_link">
    <visual>
      <origin rpy="0 0 0" xyz="0 0 0.1"/>
      <geometry>
        <box size="${base_length} ${base_width} ${base_height}"/>
      </geometry>
      <material name="blue">
        <color rgba="0 0.5 1 1"/>
      </material>
    </visual>
    <collision>
      <origin rpy="0 0 0" xyz="0 0 1"/>
      <geometry>
        <box size="${base_length} ${base_width} ${base_height}"/>
      </geometry>
    </collision>
    <inertial>
      <mass value="5"/>
      <inertia ixx="0.13" ixy="0.0" ixz="0.0" iyy="0.21" iyz="0.0" izz="0.13"/>
    </inertial>
  </link>

  <!-- Right Wheel -->
  <link name="right_wheel">
    <visual>
      <origin rpy="1.570795 0 0" xyz="0 0 0"/>
      <geometry>
        <cylinder length="0.04318" radius="0.0762"/>
      </geometry>
      <material name="darkgray">
        <color rgba=".2 .2 .2 1"/>
      </material>
    </visual>
    <collision>
      <origin rpy="1.570795 0 0" xyz="0 0 0"/>
      <geometry>
        <cylinder length="0.04318" radius="0.0762"/>
      </geometry>
    </collision>
    <inertial>
      <mass value="0.5"/>
      <inertia ixx="0.01" ixy="0.0" ixz="0.0" iyy="0.005" iyz="0.0" izz="0.005"/>
    </inertial>
  </link>

  <!-- Right Wheel Joint -->
  <joint name="joint_right_wheel" type="continuous">
    <parent link="base_link"/>
    <child link="right_wheel"/>
    <origin rpy="0 0 0" xyz="0.2 0.24 0"/>
    <axis xyz="0 1 0"/>
  </joint>

  <!-- Left Wheel -->
  <link name="left_wheel">
    <visual>
      <origin rpy="1.570795 0 0" xyz="0 0 0"/>
      <geometry>
        <cylinder length="0.04318" radius="0.0762"/>
      </geometry>
      <material name="darkgray">
        <color rgba=".2 .2 .2 1"/>
      </material>
    </visual>
    <collision>
      <origin rpy="1.570795 0 0" xyz="0 0 0"/>
      <geometry>
        <cylinder length="0.04318" radius="0.0762"/>
      </geometry>
    </collision>
    <inertial>
      <mass value="0.5"/>
      <inertia ixx="0.01" ixy="0.0" ixz="0.0" iyy="0.005" iyz="0.0" izz="0.005"/>
    </inertial>
  </link>

  <!-- Left Wheel Joint -->
  <joint name="joint_left_wheel" type="continuous">
    <parent link="base_link"/>
    <child link="left_wheel"/>
    <origin rpy="0 0 0" xyz="0.2 -0.24 0"/>
    <axis xyz="0 1 0"/>
  </joint>

  <!-- Caster Wheel -->
  <link name="caster">
    <visual>
      <origin xyz="0.0 0.0 0.0" rpy="-0.25 0.0 0.25"/>
      
      <geometry>
        <sphere radius="0.06"/>
      </geometry>
      <material name="white">
        <color rgba="1 1 1 1"/>
      </material>
    </visual>
    <collision>
      <origin xyz="0.0 0.0 0.0" rpy="-0.25 0.0 0.25s"/>
      
      <geometry>
        <sphere radius="0.06"/>
      </geometry>
    </collision>
  </link>
  <joint name="caster_joint" type="fixed">
    <origin rpy="0 0 0" xyz="-0.25 0.0 0.0"/>
    <!-- Đặt gần mặt đất để tránh nghiêng -->
    <parent link="base_link"/>
    <child link="caster"/>
  </joint>

  <!-- LiDAR -->
  <link name="laser">
    <visual>
      <geometry>
        <cylinder length="0.05" radius="0.05"/>
      </geometry>
      <material name="grass">
        <color rgba="0.3607843137254902 0.6745098039215687 0.17647058823529413 1.0"/>
      </material>
    </visual>
  </link>
  <joint name="laser_joint" type="fixed">
    <origin rpy="0 0 0" xyz="-0.15 0 0.2"/>
    <!-- Đặt về phía trước và cao hơn một chút -->
    <parent link="base_link"/>
    <child link="laser"/>
  </joint>

  <!-- Cấu hình Plugin LiDAR -->
  <gazebo reference="laser">
    <sensor type="ray" name="head_hokuyo_sensor">
      <pose>0 0 0 0 0 0</pose>
      <visualize>true</visualize>
      <update_rate>20</update_rate> <!-- Giảm tốc độ quét để hiệu suất tốt hơn -->
      <ray>
        <scan>
          <horizontal>
            <samples>360</samples> <!-- Giảm số lượng mẫu để quét phía trước -->
            <resolution>1</resolution>
            <min_angle>-1.57</min_angle>
            <max_angle>1.57</max_angle>
          </horizontal>
        </scan>
        <range>
          <min>0.1</min>
          <max>10.0</max> <!-- Giảm phạm vi để tránh quét quá xa -->
        </range>
        <noise>
          <type>gaussian</type>
          <mean>0.0</mean>
          <stddev>0.005</stddev> <!-- Giảm nhiễu để có dữ liệu quét rõ ràng hơn -->
        </noise>
      </ray>
      <plugin filename="libgazebo_ros_ray_sensor.so" name="gazebo_ros_head_hokuyo_controller">
        <ros>
          <namespace>/dd_robot</namespace>
          <remapping>cmd_vel:=cmd_vel</remapping>
        </ros>
        <topicName>/laser/scan</topicName>
        <frameName>laser</frameName>
        <output_type>sensor_msgs/LaserScan</output_type> <!-- Sử dụng LaserScan cho quét 2D phía trước -->
      </plugin>
    </sensor>
  </gazebo>

  <!-- Gazebo Plugin Diff Drive -->
  <gazebo>
    <plugin filename="libgazebo_ros_diff_drive.so" name="diff_drive_controller">
      <ros>
        <namespace>/dd_robot</namespace>
        <remapping>cmd_vel:=cmd_vel</remapping>
      </ros>
      <update_rate>50</update_rate>

      <!-- wheels -->
      <left_joint>joint_left_wheel</left_joint>
      <right_joint>joint_right_wheel</right_joint>

      <!-- kinematics -->
      <wheel_separation>0.48</wheel_separation>
      <wheel_diameter>0.1524</wheel_diameter>

      <!-- limits -->
      <max_wheel_torque>20</max_wheel_torque>
      <max_wheel_acceleration>1.0</max_wheel_acceleration>

      <command_topic>cmd_vel</command_topic>

      <!-- output -->
      <publish_odom>true</publish_odom>
      <publish_odom_tf>true</publish_odom_tf>
      <publish_wheel_tf>true</publish_wheel_tf>

      <odometry_topic>odom</odometry_topic>
      <odometry_frame>odom</odometry_frame>
      <robot_base_frame>base_footprint</robot_base_frame>
    </plugin>
  </gazebo>

</robot>
